<?xml version="1.0"?>
<robot xmlns:xacro="http://www.ros.org/wiki/xacro"  >

    <xacro:include filename="inertial_macros.xacro" />

    <material name="white">
        <color rgba="1 1 1 1" />
    </material>
    
    <material name="orange">
        <color rgba="1 0.3 0.1 1" />
    </material>

    <material name="blue">
        <color rgba="0.2 0.2 1 1" />
    </material>

    <material name="black">
        <color rgba="0 0 0 1" />
    </material>

<!-- Base link-->
    <link name="base_link">

    </link>

    <joint name="chassis_joint" type="fixed">
        <parent link="base_link"/>
        <child link="chassis"/>
        <origin xyz="-0.045 0 0"/>
    </joint>
    

<!-- chasis link-->
    <link name="chassis">
        <visual>
            <origin xyz="0.045 0.0 0.165" />
            <geometry>
                <box size="0.19 0.5 0.15"/>
            </geometry>
            <material name="white" /> 
        </visual>

        <visual>
            <origin xyz="0.33 0.0 0.10" />
            <geometry>
                <box size="0.57 0.08 0.02"/>
            </geometry>
            <material name="white" /> 
        </visual>
        
        <visual>
            <origin xyz="0.045 0.0 0.055" />
            <geometry>
                <box size="0.09 0.5 0.11"/>
            </geometry>
            <material name="white" /> 
        </visual>
        
        <collision>
            <origin xyz="0.045 0.0 0.165" />
            <geometry>
                <box size="0.19 0.5 0.15"/>
            </geometry>
        </collision>
        
        <collision>
            <origin xyz="0.045 0.0 0.165" />
            <geometry>
                <box size="0.19 0.5 0.15"/>
            </geometry>
        </collision>

        <collision>
            <origin xyz="0.045 0.0 0.055" />
            <geometry>
                <box size="0.09 0.5 0.11"/>
            </geometry>
        </collision>

        <inertial>
        <origin xyz="0.20 0.0 0" rpy="0 0 0"/>
        <mass value="1.9809343e+01"/>
        <inertia ixx="4.914e-01" iyy="2.317e-01" izz="5.354e-01"
                ixy="3.367e-16" ixz="-7.465e-03" iyz="1.793e-16"/>
        </inertial>
    </link>

    <gazebo reference="chassis">
        <material>Gazebo/White</material>
    </gazebo>

<!-- right wheel link-->
    <joint name="right_wheel_joint" type="continuous">
        <parent link="base_link"/>
        <child link="right_wheel"/>
        <origin xyz="0.0 0.28 0.02" rpy="-${pi/2} 0.0 0.0"/>
        <axis xyz="0.0 0.0 1"/>
    </joint>

    <link name="right_wheel">
        <visual>
            <geometry>
                <cylinder radius="0.1" length="0.04"/>
            </geometry>
            <material name="blue"/>
                
        </visual>

        <collision>
            <geometry>
                <cylinder radius="0.1" length="0.04"/>
            </geometry>
        </collision>
        <xacro:inertial_cylinder mass="0.1" length="0.04" radius="0.1" >
            <origin xyz="0.0 0.0 0.0" rpy="0.0 0.0 0.0"/>
        </xacro:inertial_cylinder>
    </link>

    <gazebo reference="right_wheel">
        <material>Gazebo/Blue</material>     
    </gazebo>

<!-- left wheel link-->
    <joint name="left_wheel_joint" type="continuous">
        <parent link="base_link"/>
        <child link="left_wheel"/>
        <origin xyz="0 -0.28 0.02" rpy="${pi/2} 0 0"/>
        <axis xyz="0 0 -1"/>
    </joint>

    <link name="left_wheel">
        <visual>
            <geometry>
                <cylinder radius="0.1" length="0.04"/>
            </geometry>
            <material name="blue"/>
                
        </visual>

        <collision>
            <geometry>
                <cylinder radius="0.1" length="0.04"/>
            </geometry>

        </collision>
        <xacro:inertial_cylinder mass="0.1" length="0.04" radius="0.1" >
            <origin xyz="0 0 0" rpy="0 0 0"/>
        </xacro:inertial_cylinder>
    </link>

    <gazebo reference="left_wheel">
        <material>Gazebo/Blue</material>  
    </gazebo> 
    
<!-- caster wheel link-->
    <joint name="caster_wheel_joint" type="fixed">
        <parent link="chassis"/>
        <child link="caster_wheel"/>
        <origin xyz="0.6 0 0.00" />
    </joint>

    <link name="caster_wheel">
        <visual>
            <geometry>
                <sphere radius="0.09"/>
            </geometry>
            <material name="black"/>
                
        </visual>
        <collision>
            <geometry>
                <sphere radius="0.09"/>
            </geometry>
                
        </collision>       

        <xacro:inertial_sphere mass="0.1" radius="0.05" >
            <origin xyz="0.0 0.0 0.0" rpy="0.0 0.0 0.0"/>
        </xacro:inertial_sphere> 
    </link>

    <gazebo reference="caster_wheel">
        <material>Gazebo/Black</material>
        <mu1 value="0.001"/>
        <mu2 value="0.001"/>
    </gazebo>

</robot>